Workbook

Sheet 24-26, 20-6
A1: Year | B1: case | C1: scenario | D1: Import cost (£) | E1: Export Revenue (£) | F1: Degradation cost (£) | G1: Net cost (excl. Deg., £) | H1: Net cost (incl. deg., £) | I1: Total cost per kWh | J1: Savings vs Immediate charging (£) | K1: Savings vs Immediate charging (%) | L1: Charging start hour | M1: Charging End hour | N1: include_degradation | O1: Trading Risk multiplier | P1: Trading spread threshold (£/MWh)
A2: 2024 | B2: immediate | C2: immediate | D2: 241.25277 | E2: 0 | F2: 150.39628 | G2: =D2-E2 -> 241.25277 | H2: 391.64905 | I2: 6.5274842 | J2: 0 | K2: 0 | L2: 20 | M2: 6 | N2: TRUE | O2: 1 | P2: 50
A3: 2024 | B3: smart | C3: smart | D3: 145.25861 | E3: 0 | F3: 150.35532 | G3: =D3-E3 -> 145.25861 | H3: 295.61394 | I3: 4.926899 | J3: 96.035116 | K3: 0.24520707 | L3: 20 | M3: 6 | N3: TRUE | O3: 1 | P3: 50
A4: 2024 | B4: trading | C4: profit_aware_trader | D4: 153.44104 | E4: 52.918709 | F4: 183.63616 | G4: =D4-E4 -> 100.52233 | H4: 284.1585 | I4: 4.735975 | J4: 107.49055 | K4: 0.27445631 | L4: 20 | M4: 6 | N4: TRUE | O4: 1 | P4: 50
A5: 2024 | B5: trading_boosted | C5: profit_aware_trader | D5: 227.72889 | E5: 188.77834 | F5: 272.16548 | G5: =D5-E5 -> 38.95055 | H5: 311.11603 | I5: 5.1852672 | J5: 80.533024 | K5: 0.20562548 | L5: 20 | M5: 6 | N5: TRUE | O5: 0.5 | P5: 25
A6: 2025 | B6: immediate | C6: immediate | D6: 272.81659 | E6: 0 | F6: 150 | G6: =D6-E6 -> 272.81659 | H6: 422.81659 | I6: 7.0469432 | J6: 0 | K6: 0 | L6: 20 | M6: 6 | N6: TRUE | O6: 1 | P6: 50
A7: 2025 | B7: smart | C7: smart | D7: 179.89221 | E7: 0 | F7: 149.63 | G7: =D7-E7 -> 179.89221 | H7: 329.52221 | I7: 5.4920368 | J7: 93.294382 | K7: 0.22064977 | L7: 20 | M7: 6 | N7: TRUE | O7: 1 | P7: 50
A8: 2025 | B8: trading | C8: profit_aware_trader | D8: 194.9765 | E8: 61.787829 | F8: 184.57808 | G8: =D8-E8 -> 133.18867 | H8: 317.76675 | I8: 5.2961125 | J8: 105.04984 | K8: 0.24845251 | L8: 20 | M8: 6 | N8: TRUE | O8: 1 | P8: 50
A9: 2025 | B9: trading_boosted | C9: profit_aware_trader | D9: 281.92337 | E9: 204.37471 | F9: 264.36164 | G9: =D9-E9 -> 77.548655 | H9: 341.9103 | I9: 5.698505 | J9: 80.906291 | K9: 0.1913508 | L9: 20 | M9: 6 | N9: TRUE | O9: 0.5 | P9: 25
A10: 2026 | B10: immediate | C10: immediate | D10: 160.95322 | E10: 0 | F10: 73.561644 | G10: =D10-E10 -> 160.95322 | H10: 234.51486 | I10: 3.9085811 | J10: 0 | K10: 0 | L10: 20 | M10: 6 | N10: TRUE | O10: 1 | P10: 50
A11: 2026 | B11: smart | C11: smart | D11: 113.29254 | E11: 0 | F11: 73.972603 | G11: =D11-E11 -> 113.29254 | H11: 187.26514 | I11: 3.1210857 | J11: 47.249722 | K11: 0.20147858 | L11: 20 | M11: 6 | N11: TRUE | O11: 1 | P11: 50
A12: 2026 | B12: trading | C12: profit_aware_trader | D12: 121.75325 | E12: 29.305615 | F12: 86.703767 | G12: =D12-E12 -> 92.447635 | H12: 179.1514 | I12: 2.9858567 | J12: 55.363461 | K12: 0.23607656 | L12: 20 | M12: 6 | N12: TRUE | O12: 1 | P12: 50
A13: 2026 | B13: trading_boosted | C13: profit_aware_trader | D13: 192.4266 | E13: 131.47537 | F13: 132.63342 | G13: =D13-E13 -> 60.951228 | H13: 193.58465 | I13: 3.2264109 | J13: 40.930211 | K13: 0.17453142 | L13: 20 | M13: 6 | N13: TRUE | O13: 0.5 | P13: 25
A14: all | B14: immediate | C14: immediate | D14: 675.02258 | E14: 0 | F14: 373.95793 | G14: =D14-E14 -> 675.02258 | H14: 1048.9805 | I14: 17.483008 | J14: 0 | K14: 0 | L14: 20 | M14: 6 | N14: TRUE | O14: 1 | P14: 50
A15: all | B15: smart | C15: smart | D15: 438.44336 | E15: 0 | F15: 373.95793 | G15: =D15-E15 -> 438.44336 | H15: 812.40129 | I15: 13.540021 | J15: 236.57922 | K15: 0.22553252 | L15: 20 | M15: 6 | N15: TRUE | O15: 1 | P15: 50
A16: all | B16: trading | C16: profit_aware_trader | D16: 470.17079 | E16: 144.01215 | F16: 454.91801 | G16: =D16-E16 -> 326.15864 | H16: 781.07665 | I16: 13.017944 | J16: 267.90386 | K16: 0.25539451 | L16: 20 | M16: 6 | N16: TRUE | O16: 1 | P16: 50
A17: all | B17: trading_boosted | C17: profit_aware_trader | D17: 702.07886 | E17: 524.62843 | F17: 669.16055 | G17: =D17-E17 -> 177.45043 | H17: 846.61098 | I17: 14.110183 | J17: 202.36953 | K17: 0.1929202 | L17: 20 | M17: 6 | N17: TRUE | O17: 0.5 | P17: 25
E19: =E21/G42 -> 270.75082
A20: No degradation | B20: 2024 | C20: 2025 | D20: 2026 | E20: Total 24-26
A21: immediate | B21: =G2 -> 241.25277 | C21: =G6 -> 272.81659 | D21: =G10 -> 160.95322 | E21: =G14 -> 675.02258
A22: smart | B22: =G3 -> 145.25861 | C22: =G7 -> 179.89221 | D22: =G11 -> 113.29254 | E22: =G15 -> 438.44336
A23: trading | B23: =G4 -> 100.52233 | C23: =G8 -> 133.18867 | D23: =G12 -> 92.447635 | E23: =G16 -> 326.15864
A24: trading boosted | B24: =G5 -> 38.95055 | C24: =G9 -> 77.548655 | D24: =G13 -> 60.951228 | E24: =G17 -> 177.45043
A26: No degradation | B26: 2024 | C26: 2025 | D26: 2026 | E26: Total
A27: immediate | B27: =(B21-B$21)*-1 -> 0 | C27: =(C21-C$21)*-1 -> 0 | D27: =(D21-D$21)*-1 -> 0 | E27: =(E21-E$21)*-1 -> 0
A28: smart | B28: =(B22-B$21)*-1 -> 95.994157 | C28: =(C22-C$21)*-1 -> 92.924382 | D28: =(D22-D$21)*-1 -> 47.660681 | E28: =(E22-E$21)*-1 -> 236.57922
A29: trading | B29: =(B23-B$21)*-1 -> 140.73044 | C29: =(C23-C$21)*-1 -> 139.62792 | D29: =(D23-D$21)*-1 -> 68.505585 | E29: =(E23-E$21)*-1 -> 348.86395
A30: trading boosted | B30: =(B24-B$21)*-1 -> 202.30222 | C30: =(C24-C$21)*-1 -> 195.26793 | D30: =(D24-D$21)*-1 -> 100.00199 | E30: =(E24-E$21)*-1 -> 497.57215
A32: Degradation | B32: 2024 | C32: 2025 | D32: 2026 | E32: Total
A33: immediate | B33: =H2 -> 391.64905 | C33: =H6 -> 422.81659 | D33: =H10 -> 234.51486 | E33: =H14 -> 1048.9805
A34: smart | B34: =H3 -> 295.61394 | C34: =H7 -> 329.52221 | D34: =H11 -> 187.26514 | E34: =H15 -> 812.40129
A35: trading | B35: =H4 -> 284.1585 | C35: =H8 -> 317.76675 | D35: =H12 -> 179.1514 | E35: =H16 -> 781.07665
A36: trading boosted | B36: =H5 -> 311.11603 | C36: =H9 -> 341.9103 | D36: =H13 -> 193.58465 | E36: =H17 -> 846.61098
A38: Degradation | B38: 2024 | C38: 2025 | D38: 2026 | E38: Total
A39: immediate | B39: =(B33-B$33)*-1 -> 0 | C39: =(C33-C$33)*-1 -> 0 | D39: =(D33-D$33)*-1 -> 0 | E39: =(E33-E$33)*-1 -> 0 | F39: Date start | G39: 45292
A40: smart | B40: =(B34-B$33)*-1 -> 96.035116 | C40: =(C34-C$33)*-1 -> 93.294382 | D40: =(D34-D$33)*-1 -> 47.249722 | E40: =(E34-E$33)*-1 -> 236.57922 | F40: Date end | G40: 46202
A41: trading | B41: =(B35-B$33)*-1 -> 107.49055 | C41: =(C35-C$33)*-1 -> 105.04984 | D41: =(D35-D$33)*-1 -> 55.363461 | E41: =(E35-E$33)*-1 -> 267.90386 | F41: Days | G41: =G40-G39 -> 910
A42: trading boosted | B42: =(B36-B$33)*-1 -> 80.533024 | C42: =(C36-C$33)*-1 -> 80.906291 | D42: =(D36-D$33)*-1 -> 40.930211 | E42: =(E36-E$33)*-1 -> 202.36953 | F42: Years | G42: =G41/365 -> 2.4931507
A44: No degradation | B44: Total - 20.00-6.00 | C44: Total - 19.00-6.00 | D44: Total - 18.00-6.00
A45: immediate | B45: =E27/$G$42 -> 0 | C45: ='24-26, 19-6'!E27/$G$42 -> 0 | D45: ='24-26, 18-6'!E27/$G$42 -> 0
...

Sheet 24-26, 19-6
A1: year | B1: case | C1: scenario | D1: import_cost_gbp | E1: export_revenue_gbp | F1: degradation_cost_gbp | H1: total_cost_gbp | I1: total_cost_gbp_per_battery_kwh | J1: saving_vs_immediate_gbp | K1: saving_vs_immediate_pct | L1: charging_start_hour | M1: charging_end_hour | N1: include_degradation | O1: trading_risk_multiplier | P1: degradation_threshold_gbp_per_mwh
A2: 2024 | B2: immediate | C2: immediate | D2: 260.39704 | E2: 0 | F2: 150.39515 | G2: =D2-E2 -> 260.39704 | H2: 410.79219 | I2: 6.8465366 | J2: 0 | K2: 0 | L2: 19 | M2: 6 | N2: TRUE | O2: 1 | P2: 50
A3: 2024 | B3: smart | C3: smart | D3: 145.25863 | E3: 0 | F3: 150.35419 | G3: =D3-E3 -> 145.25863 | H3: 295.61283 | I3: 4.9268804 | J3: 115.17937 | K3: 0.28038354 | L3: 19 | M3: 6 | N3: TRUE | O3: 1 | P3: 50
A4: 2024 | B4: trading | C4: profit_aware_trader | D4: 162.58092 | E4: 90.369676 | F4: 203.90158 | G4: =D4-E4 -> 72.211249 | H4: 276.11282 | I4: 4.6018804 | J4: 134.67937 | K4: 0.3278528 | L4: 19 | M4: 6 | N4: TRUE | O4: 1 | P4: 50
A5: 2024 | B5: trading_boosted | C5: profit_aware_trader | D5: 283.82716 | E5: 296.98536 | F5: 326.9244 | G5: =D5-E5 -> -13.158203 | H5: 313.7662 | I5: 5.2294366 | J5: 97.025998 | K5: 0.23619241 | L5: 19 | M5: 6 | N5: TRUE | O5: 0.5 | P5: 25
A6: 2025 | B6: immediate | C6: immediate | D6: 298.17968 | E6: 0 | F6: 150 | G6: =D6-E6 -> 298.17968 | H6: 448.17968 | I6: 7.4696614 | J6: 0 | K6: 0 | L6: 19 | M6: 6 | N6: TRUE | O6: 1 | P6: 50
A7: 2025 | B7: smart | C7: smart | D7: 179.7979 | E7: 0 | F7: 149.63 | G7: =D7-E7 -> 179.7979 | H7: 329.4279 | I7: 5.490465 | J7: 118.75178 | K7: 0.26496467 | L7: 19 | M7: 6 | N7: TRUE | O7: 1 | P7: 50
A8: 2025 | B8: trading | C8: profit_aware_trader | D8: 209.33262 | E8: 107.38292 | F8: 204.84349 | G8: =D8-E8 -> 101.9497 | H8: 306.7932 | I8: 5.11322 | J8: 141.38648 | K8: 0.3154683 | L8: 19 | M8: 6 | N8: TRUE | O8: 1 | P8: 50
A9: 2025 | B9: trading_boosted | C9: profit_aware_trader | D9: 358.97605 | E9: 337.49705 | F9: 321.79404 | G9: =D9-E9 -> 21.478992 | H9: 343.27303 | I9: 5.7212172 | J9: 104.90665 | K9: 0.23407274 | L9: 19 | M9: 6 | N9: TRUE | O9: 0.5 | P9: 25
A10: 2026 | B10: immediate | C10: immediate | D10: 172.74274 | E10: 0 | F10: 73.561644 | G10: =D10-E10 -> 172.74274 | H10: 246.30438 | I10: 4.1050731 | J10: 0 | K10: 0 | L10: 19 | M10: 6 | N10: TRUE | O10: 1 | P10: 50
A11: 2026 | B11: smart | C11: smart | D11: 113.28346 | E11: 0 | F11: 73.972603 | G11: =D11-E11 -> 113.28346 | H11: 187.25606 | I11: 3.1209343 | J11: 59.048325 | K11: 0.23973721 | L11: 19 | M11: 6 | N11: TRUE | O11: 1 | P11: 50
A12: 2026 | B12: trading | C12: profit_aware_trader | D12: 132.33736 | E12: 54.813628 | F12: 94.809932 | G12: =D12-E12 -> 77.52373 | H12: 172.33366 | I12: 2.8722277 | J12: 73.970723 | K12: 0.3003224 | L12: 19 | M12: 6 | N12: TRUE | O12: 1 | P12: 50
A13: 2026 | B13: trading_boosted | C13: profit_aware_trader | D13: 241.60619 | E13: 208.72079 | F13: 161.005 | G13: =D13-E13 -> 32.885396 | H13: 193.8904 | I13: 3.2315066 | J13: 52.413989 | K13: 0.21280169 | L13: 19 | M13: 6 | N13: TRUE | O13: 0.5 | P13: 25
A14: all | B14: immediate | C14: immediate | D14: 731.31946 | E14: 0 | F14: 373.9568 | G14: =D14-E14 -> 731.31946 | H14: 1105.2763 | I14: 18.421271 | J14: 0 | K14: 0 | L14: 19 | M14: 6 | N14: TRUE | O14: 1 | P14: 50
A15: all | B15: smart | C15: smart | D15: 438.33999 | E15: 0 | F15: 373.9568 | G15: =D15-E15 -> 438.33999 | H15: 812.29678 | I15: 13.53828 | J15: 292.97948 | K15: 0.26507353 | L15: 19 | M15: 6 | N15: TRUE | O15: 1 | P15: 50
A16: all | B16: trading | C16: profit_aware_trader | D16: 504.2509 | E16: 252.56622 | F16: 503.555 | G16: =D16-E16 -> 251.68468 | H16: 755.23968 | I16: 12.587328 | J16: 350.03658 | K16: 0.31669601 | L16: 19 | M16: 6 | N16: TRUE | O16: 1 | P16: 50
A17: all | B17: trading_boosted | C17: profit_aware_trader | D17: 884.40939 | E17: 843.20321 | F17: 809.72344 | G17: =D17-E17 -> 41.206186 | H17: 850.92963 | I17: 14.18216 | J17: 254.34663 | K17: 0.23012042 | L17: 19 | M17: 6 | N17: TRUE | O17: 0.5 | P17: 25
B20: 2024 | C20: 2025 | D20: 2026 | E20: Total
A21: immediate | B21: =G2 -> 260.39704 | C21: =G6 -> 298.17968 | D21: =G10 -> 172.74274 | E21: =G14 -> 731.31946
A22: smart | B22: =G3 -> 145.25863 | C22: =G7 -> 179.7979 | D22: =G11 -> 113.28346 | E22: =G15 -> 438.33999
A23: trading | B23: =G4 -> 72.211249 | C23: =G8 -> 101.9497 | D23: =G12 -> 77.52373 | E23: =G16 -> 251.68468
A24: trading_boosted | B24: =G5 -> -13.158203 | C24: =G9 -> 21.478992 | D24: =G13 -> 32.885396 | E24: =G17 -> 41.206186
B26: 2024 | C26: 2025 | D26: 2026 | E26: Total
A27: immediate | B27: =(B21-B$21)*-1 -> 0 | C27: =(C21-C$21)*-1 -> 0 | D27: =(D21-D$21)*-1 -> 0 | E27: =(E21-E$21)*-1 -> 0
A28: smart | B28: =(B22-B$21)*-1 -> 115.13841 | C28: =(C22-C$21)*-1 -> 118.38178 | D28: =(D22-D$21)*-1 -> 59.459284 | E28: =(E22-E$21)*-1 -> 292.97948
A29: trading | B29: =(B23-B$21)*-1 -> 188.18579 | C29: =(C23-C$21)*-1 -> 196.22998 | D29: =(D23-D$21)*-1 -> 95.219011 | E29: =(E23-E$21)*-1 -> 479.63478
A30: trading_boosted | B30: =(B24-B$21)*-1 -> 273.55524 | C30: =(C24-C$21)*-1 -> 276.70069 | D30: =(D24-D$21)*-1 -> 139.85734 | E30: =(E24-E$21)*-1 -> 690.11328
A32: Degradation | B32: 2024 | C32: 2025 | D32: 2026 | E32: Total
A33: immediate | B33: =H2 -> 410.79219 | C33: =H6 -> 448.17968 | D33: =H10 -> 246.30438 | E33: =H14 -> 1105.2763
A34: smart | B34: =H3 -> 295.61283 | C34: =H7 -> 329.4279 | D34: =H11 -> 187.25606 | E34: =H15 -> 812.29678
A35: trading | B35: =H4 -> 276.11282 | C35: =H8 -> 306.7932 | D35: =H12 -> 172.33366 | E35: =H16 -> 755.23968
A36: trading_boosted | B36: =H5 -> 313.7662 | C36: =H9 -> 343.27303 | D36: =H13 -> 193.8904 | E36: =H17 -> 850.92963
A38: Degradation | B38: 2024 | C38: 2025 | D38: 2026 | E38: Total
A39: immediate | B39: =(B33-B$33)*-1 -> 0 | C39: =(C33-C$33)*-1 -> 0 | D39: =(D33-D$33)*-1 -> 0 | E39: =(E33-E$33)*-1 -> 0
A40: smart | B40: =(B34-B$33)*-1 -> 115.17937 | C40: =(C34-C$33)*-1 -> 118.75178 | D40: =(D34-D$33)*-1 -> 59.048325 | E40: =(E34-E$33)*-1 -> 292.97948
A41: trading | B41: =(B35-B$33)*-1 -> 134.67937 | C41: =(C35-C$33)*-1 -> 141.38648 | D41: =(D35-D$33)*-1 -> 73.970723 | E41: =(E35-E$33)*-1 -> 350.03658
A42: trading_boosted | B42: =(B36-B$33)*-1 -> 97.025998 | C42: =(C36-C$33)*-1 -> 104.90665 | D42: =(D36-D$33)*-1 -> 52.413989 | E42: =(E36-E$33)*-1 -> 254.34663

Sheet 24-26, 18-6
A1: year | B1: case | C1: scenario | D1: import_cost_gbp | E1: export_revenue_gbp | F1: degradation_cost_gbp | H1: total_cost_gbp | I1: total_cost_gbp_per_battery_kwh | J1: saving_vs_immediate_gbp | K1: saving_vs_immediate_pct | L1: charging_start_hour | M1: charging_end_hour | N1: include_degradation | O1: trading_risk_multiplier | P1: degradation_threshold_gbp_per_mwh
A2: 2024 | B2: immediate | C2: immediate | D2: 282.18784 | E2: 0 | F2: 150.39384 | G2: =D2-E2 -> 282.18784 | H2: 432.58168 | I2: 7.2096946 | J2: 0 | K2: 0 | L2: 18 | M2: 6 | N2: TRUE | O2: 1 | P2: 50
A3: 2024 | B3: smart | C3: smart | D3: 145.25531 | E3: 0 | F3: 150.35288 | G3: =D3-E3 -> 145.25531 | H3: 295.60819 | I3: 4.9268031 | J3: 136.97349 | K3: 0.31664191 | L3: 18 | M3: 6 | N3: TRUE | O3: 1 | P3: 50
A4: 2024 | B4: trading | C4: profit_aware_trader | D4: 180.23245 | E4: 146.99467 | F4: 229.21144 | G4: =D4-E4 -> 33.237781 | H4: 262.44922 | I4: 4.3741537 | J4: 170.13246 | K4: 0.39329557 | L4: 18 | M4: 6 | N4: TRUE | O4: 1 | P4: 50
A5: 2024 | B5: trading_boosted | C5: profit_aware_trader | D5: 360.43147 | E5: 434.78942 | F5: 388.22158 | G5: =D5-E5 -> -74.357949 | H5: 313.86363 | I5: 5.2310604 | J5: 118.71805 | K5: 0.27444077 | L5: 18 | M5: 6 | N5: TRUE | O5: 0.5 | P5: 25
A6: 2025 | B6: immediate | C6: immediate | D6: 326.20435 | E6: 0 | F6: 150 | G6: =D6-E6 -> 326.20435 | H6: 476.20435 | I6: 7.9367392 | J6: 0 | K6: 0 | L6: 18 | M6: 6 | N6: TRUE | O6: 1 | P6: 50
A7: 2025 | B7: smart | C7: smart | D7: 179.70002 | E7: 0 | F7: 149.63 | G7: =D7-E7 -> 179.70002 | H7: 329.33002 | I7: 5.4888337 | J7: 146.87433 | K7: 0.30842711 | L7: 18 | M7: 6 | N7: TRUE | O7: 1 | P7: 50
A8: 2025 | B8: trading | C8: profit_aware_trader | D8: 237.38001 | E8: 184.25531 | F8: 232.62623 | G8: =D8-E8 -> 53.124699 | H8: 285.75093 | I8: 4.7625155 | J8: 190.45342 | K8: 0.39994053 | L8: 18 | M8: 6 | N8: TRUE | O8: 1 | P8: 50
A9: 2025 | B9: trading_boosted | C9: profit_aware_trader | D9: 459.08587 | E9: 513.89692 | F9: 388.87918 | G9: =D9-E9 -> -54.811048 | H9: 334.06813 | I9: 5.5678022 | J9: 142.13622 | K9: 0.29847737 | L9: 18 | M9: 6 | N9: TRUE | O9: 0.5 | P9: 25
A10: 2026 | B10: immediate | C10: immediate | D10: 179.33981 | E10: 0 | F10: 73.561644 | G10: =D10-E10 -> 179.33981 | H10: 252.90146 | I10: 4.2150243 | J10: 0 | K10: 0 | L10: 18 | M10: 6 | N10: TRUE | O10: 1 | P10: 50
A11: 2026 | B11: smart | C11: smart | D11: 113.10811 | E11: 0 | F11: 73.972603 | G11: =D11-E11 -> 113.10811 | H11: 187.08072 | I11: 3.1180119 | J11: 65.820742 | K11: 0.26026241 | L11: 18 | M11: 6 | N11: TRUE | O11: 1 | P11: 50
A12: 2026 | B12: trading | C12: profit_aware_trader | D12: 147.0048 | E12: 87.697255 | F12: 106.02726 | G12: =D12-E12 -> 59.307543 | H12: 165.3348 | I12: 2.7555801 | J12: 87.566653 | K12: 0.34624812 | L12: 18 | M12: 6 | N12: TRUE | O12: 1 | P12: 50
A13: 2026 | B13: trading_boosted | C13: profit_aware_trader | D13: 296.90802 | E13: 295.67435 | F13: 191.88199 | G13: =D13-E13 -> 1.2336668 | H13: 193.11565 | I13: 3.2185942 | J13: 59.785803 | K13: 0.2363996 | L13: 18 | M13: 6 | N13: TRUE | O13: 0.5 | P13: 25
A14: all | B14: immediate | C14: immediate | D14: 787.73201 | E14: 0 | F14: 373.95548 | G14: =D14-E14 -> 787.73201 | H14: 1161.6875 | I14: 19.361458 | J14: 0 | K14: 0 | L14: 18 | M14: 6 | N14: TRUE | O14: 1 | P14: 50
A15: all | B15: smart | C15: smart | D15: 438.06344 | E15: 0 | F15: 373.95548 | G15: =D15-E15 -> 438.06344 | H15: 812.01892 | I15: 13.533649 | J15: 349.66856 | K15: 0.30100054 | L15: 18 | M15: 6 | N15: TRUE | O15: 1 | P15: 50
A16: all | B16: trading | C16: profit_aware_trader | D16: 564.61726 | E16: 418.94724 | F16: 567.86493 | G16: =D16-E16 -> 145.67002 | H16: 713.53495 | I16: 11.892249 | J16: 448.15253 | K16: 0.38577719 | L16: 18 | M16: 6 | N16: TRUE | O16: 1 | P16: 50
A17: all | B17: trading_boosted | C17: profit_aware_trader | D17: 1116.4254 | E17: 1244.3607 | F17: 968.98274 | G17: =D17-E17 -> -127.93533 | H17: 841.04741 | I17: 14.017457 | J17: 320.64008 | K17: 0.27601234 | L17: 18 | M17: 6 | N17: TRUE | O17: 0.5 | P17: 25
B20: 2024 | C20: 2025 | D20: 2026 | E20: Total
A21: immediate | B21: =G2 -> 282.18784 | C21: =G6 -> 326.20435 | D21: =G10 -> 179.33981 | E21: =G14 -> 787.73201
A22: smart | B22: =G3 -> 145.25531 | C22: =G7 -> 179.70002 | D22: =G11 -> 113.10811 | E22: =G15 -> 438.06344
A23: trading | B23: =G4 -> 33.237781 | C23: =G8 -> 53.124699 | D23: =G12 -> 59.307543 | E23: =G16 -> 145.67002
A24: trading_boosted | B24: =G5 -> -74.357949 | C24: =G9 -> -54.811048 | D24: =G13 -> 1.2336668 | E24: =G17 -> -127.93533
B26: 2024 | C26: 2025 | D26: 2026 | E26: Total
A27: immediate | B27: =(B21-B$21)*-1 -> 0 | C27: =(C21-C$21)*-1 -> 0 | D27: =(D21-D$21)*-1 -> 0 | E27: =(E21-E$21)*-1 -> 0
A28: smart | B28: =(B22-B$21)*-1 -> 136.93253 | C28: =(C22-C$21)*-1 -> 146.50433 | D28: =(D22-D$21)*-1 -> 66.2317 | E28: =(E22-E$21)*-1 -> 349.66856
A29: trading | B29: =(B23-B$21)*-1 -> 248.95006 | C29: =(C23-C$21)*-1 -> 273.07965 | D29: =(D23-D$21)*-1 -> 120.03227 | E29: =(E23-E$21)*-1 -> 642.06198
A30: trading_boosted | B30: =(B24-B$21)*-1 -> 356.54579 | C30: =(C24-C$21)*-1 -> 381.0154 | D30: =(D24-D$21)*-1 -> 178.10615 | E30: =(E24-E$21)*-1 -> 915.66734
A32: Degradation | B32: 2024 | C32: 2025 | D32: 2026 | E32: Total
A33: immediate | B33: =H2 -> 432.58168 | C33: =H6 -> 476.20435 | D33: =H10 -> 252.90146 | E33: =H14 -> 1161.6875
A34: smart | B34: =H3 -> 295.60819 | C34: =H7 -> 329.33002 | D34: =H11 -> 187.08072 | E34: =H15 -> 812.01892
A35: trading | B35: =H4 -> 262.44922 | C35: =H8 -> 285.75093 | D35: =H12 -> 165.3348 | E35: =H16 -> 713.53495
A36: trading_boosted | B36: =H5 -> 313.86363 | C36: =H9 -> 334.06813 | D36: =H13 -> 193.11565 | E36: =H17 -> 841.04741
A38: Degradation | B38: 2024 | C38: 2025 | D38: 2026 | E38: Total
A39: immediate | B39: =(B33-B$33)*-1 -> 0 | C39: =(C33-C$33)*-1 -> 0 | D39: =(D33-D$33)*-1 -> 0 | E39: =(E33-E$33)*-1 -> 0
A40: smart | B40: =(B34-B$33)*-1 -> 136.97349 | C40: =(C34-C$33)*-1 -> 146.87433 | D40: =(D34-D$33)*-1 -> 65.820742 | E40: =(E34-E$33)*-1 -> 349.66856
A41: trading | B41: =(B35-B$33)*-1 -> 170.13246 | C41: =(C35-C$33)*-1 -> 190.45342 | D41: =(D35-D$33)*-1 -> 87.566653 | E41: =(E35-E$33)*-1 -> 448.15253
A42: trading_boosted | B42: =(B36-B$33)*-1 -> 118.71805 | C42: =(C36-C$33)*-1 -> 142.13622 | D42: =(D36-D$33)*-1 -> 59.785803 | E42: =(E36-E$33)*-1 -> 320.64008
